In JavaScript, promises are objects used to handle asynchronous operations. They represent a value that may be available now, or in the future, or never. Promises have methods like `.then()` and `.catch()` that allow you to handle the result of asynchronous operations.

Here's a brief explanation of `.then()` and `.catch()`:

1. `.then()`: This method is used to register a callback function to be executed when the promise is resolved. It takes two optional arguments: a callback function for the success case, and a callback function for the failure case.

2. `.catch()`: This method is used to register a callback function to be executed when the promise is rejected (i.e., an error occurs). It is essentially a shorthand for `.then(null, errorCallback)`.

Here's a simple example demonstrating the usage of promises, `.then()`, and `.catch()`:

```javascript
function asyncOperation() {
    return new Promise((resolve, reject) => {
        // Simulating an asynchronous operation (e.g., fetching data)
        setTimeout(() => {
            const success = true; // Change to false to simulate failure
            if (success) {
                resolve("Operation successful"); // Resolve the promise
            } else {
                reject(new Error("Operation failed")); // Reject the promise with an error
            }
        }, 2000); // Simulating a 2-second delay
    });
}

// Using the promise
asyncOperation()
    .then(result => {
        console.log("Success:", result);
        // Code to handle successful operation
    })
    .catch(error => {
        console.error("Error:", error.message);
        // Code to handle error
    });
```

In this example:

- `asyncOperation()` returns a promise that resolves after a 2-second delay.
- `.then()` is used to handle the resolved value (success case).
- `.catch()` is used to handle any errors that may occur during the execution of the promise.

We can chain multiple `.then()` calls to handle a sequence of asynchronous operations, with each `.then()` receiving the result of the previous one. If an error occurs at any point in the chain, the control will jump to the nearest `.catch()` block for error handling.
